Workbook

Sheet Resumen
A1: Resumen por cluster
A3: Cluster | B3: Nº palabras | C3: Prioridad alta | D3: Volumen total (cuando lo rellenéis)
A4: A domicilio (núcleo) | B4: =COUNTIF('Mapa palabras clave'!$A$5:$A$59,A4) -> 5 | C4: =COUNTIFS('Mapa palabras clave'!$A$5:$A$59,A4,'Mapa palabras clave'!$D$5:$D$59,"Alta") -> 2 | D4: =SUMIF('Mapa palabras clave'!$A$5:$A$59,A4,'Mapa palabras clave'!$G$5:$G$59) -> 0
A5: Autismo / TEA | B5: =COUNTIF('Mapa palabras clave'!$A$5:$A$59,A5) -> 8 | C5: =COUNTIFS('Mapa palabras clave'!$A$5:$A$59,A5,'Mapa palabras clave'!$D$5:$D$59,"Alta") -> 5 | D5: =SUMIF('Mapa palabras clave'!$A$5:$A$59,A5,'Mapa palabras clave'!$G$5:$G$59) -> 0
A6: TDAH | B6: =COUNTIF('Mapa palabras clave'!$A$5:$A$59,A6) -> 5 | C6: =COUNTIFS('Mapa palabras clave'!$A$5:$A$59,A6,'Mapa palabras clave'!$D$5:$D$59,"Alta") -> 2 | D6: =SUMIF('Mapa palabras clave'!$A$5:$A$59,A6,'Mapa palabras clave'!$G$5:$G$59) -> 0
A7: Neurodesarrollo | B7: =COUNTIF('Mapa palabras clave'!$A$5:$A$59,A7) -> 4 | C7: =COUNTIFS('Mapa palabras clave'!$A$5:$A$59,A7,'Mapa palabras clave'!$D$5:$D$59,"Alta") -> 0 | D7: =SUMIF('Mapa palabras clave'!$A$5:$A$59,A7,'Mapa palabras clave'!$G$5:$G$59) -> 0
A8: Diagnóstico / neuropsicología | B8: =COUNTIF('Mapa palabras clave'!$A$5:$A$59,A8) -> 6 | C8: =COUNTIFS('Mapa palabras clave'!$A$5:$A$59,A8,'Mapa palabras clave'!$D$5:$D$59,"Alta") -> 4 | D8: =SUMIF('Mapa palabras clave'!$A$5:$A$59,A8,'Mapa palabras clave'!$G$5:$G$59) -> 0
A9: Sombra / colegio | B9: =COUNTIF('Mapa palabras clave'!$A$5:$A$59,A9) -> 7 | C9: =COUNTIFS('Mapa palabras clave'!$A$5:$A$59,A9,'Mapa palabras clave'!$D$5:$D$59,"Alta") -> 3 | D9: =SUMIF('Mapa palabras clave'!$A$5:$A$59,A9,'Mapa palabras clave'!$G$5:$G$59) -> 0
A10: Terapia ocupacional | B10: =COUNTIF('Mapa palabras clave'!$A$5:$A$59,A10) -> 6 | C10: =COUNTIFS('Mapa palabras clave'!$A$5:$A$59,A10,'Mapa palabras clave'!$D$5:$D$59,"Alta") -> 3 | D10: =SUMIF('Mapa palabras clave'!$A$5:$A$59,A10,'Mapa palabras clave'!$G$5:$G$59) -> 0
A11: Logopedia | B11: =COUNTIF('Mapa palabras clave'!$A$5:$A$59,A11) -> 4 | C11: =COUNTIFS('Mapa palabras clave'!$A$5:$A$59,A11,'Mapa palabras clave'!$D$5:$D$59,"Alta") -> 2 | D11: =SUMIF('Mapa palabras clave'!$A$5:$A$59,A11,'Mapa palabras clave'!$G$5:$G$59) -> 0
A12: Psicología infantil | B12: =COUNTIF('Mapa palabras clave'!$A$5:$A$59,A12) -> 3 | C12: =COUNTIFS('Mapa palabras clave'!$A$5:$A$59,A12,'Mapa palabras clave'!$D$5:$D$59,"Alta") -> 1 | D12: =SUMIF('Mapa palabras clave'!$A$5:$A$59,A12,'Mapa palabras clave'!$G$5:$G$59) -> 0
A13: Ayudas | B13: =COUNTIF('Mapa palabras clave'!$A$5:$A$59,A13) -> 5 | C13: =COUNTIFS('Mapa palabras clave'!$A$5:$A$59,A13,'Mapa palabras clave'!$D$5:$D$59,"Alta") -> 2 | D13: =SUMIF('Mapa palabras clave'!$A$5:$A$59,A13,'Mapa palabras clave'!$G$5:$G$59) -> 0
A14: Local | B14: =COUNTIF('Mapa palabras clave'!$A$5:$A$59,A14) -> 2 | C14: =COUNTIFS('Mapa palabras clave'!$A$5:$A$59,A14,'Mapa palabras clave'!$D$5:$D$59,"Alta") -> 1 | D14: =SUMIF('Mapa palabras clave'!$A$5:$A$59,A14,'Mapa palabras clave'!$G$5:$G$59) -> 0
A15: Total | B15: =SUM(B4:B14) -> 55 | C15: =SUM(C4:C14) -> 25 | D15: =SUM(D4:D14) -> 0
A17: Cómo leerlo: 'Volumen total' se calcula solo cuando rellenéis la columna amarilla de la hoja 'Mapa palabras clave'.

Sheet Mapa palabras clave
A1: Proyecto PasiTOs · Mapa de palabras clave para la web
A2: Leyenda: las celdas amarillas de 'Volumen mensual' se rellenan con Google Keyword Planner o Search Console (no hay datos de volumen públicos fiables). Prioridad = encaje con vuestros servicios + intención de contratar + competencia observada. Fecha: 29-09-2026.
A4: Cluster | B4: Palabra clave | C4: Intención | D4: Prioridad | E4: Página destino propuesta | F4: Competidores que la trabajan | G4: Volumen mensual (rellenar) | H4: Uso en la web | I4: Notas
A5: A domicilio (núcleo) | B5: terapia infantil a domicilio madrid | C5: Transaccional | D5: Alta | E5: / (home) | F5: Codo con Codo TEA, Eva Téllez | H5: Title + H1 home | I5: Vuestra diferencia principal. Pocas webs la trabajan como paraguas de varias terapias.
A6: A domicilio (núcleo) | B6: terapia a domicilio niños madrid | C6: Transaccional | D6: Alta | E6: / (home) | F6: Codo con Codo TEA | H6: H2 home
A7: A domicilio (núcleo) | B7: terapia en casa para niños | C7: Transaccional | D7: Media | E7: / (home) | F7: Terapia ocupacional en casa | H7: Texto home
A8: A domicilio (núcleo) | B8: terapia en entorno natural niños | C8: Informativa | D8: Media | E8: /por-que-en-casa-y-en-el-cole | F8: Abaterapia, Felisa Casado | H8: H1 página 'por qué' | I8: Término técnico; acompañar siempre de 'a domicilio'.
A9: A domicilio (núcleo) | B9: terapeuta infantil a domicilio | C9: Transaccional | D9: Media | E9: / (home) | H9: Texto home
A10: Autismo / TEA | B10: terapia autismo madrid | C10: Transaccional | D10: Alta | E10: /autismo-tea | F10: Centro Juntos, Abaterapia, Apraxia | H10: Title + H1 | I10: Alta competencia de centros; ganar con 'a domicilio'.
A11: Autismo / TEA | B11: terapia a domicilio niños con autismo | C11: Transaccional | D11: Alta | E11: /autismo-tea | F11: Codo con Codo TEA | H11: H1 / H2 | I11: Competidor más directo usa exactamente esta frase en su title.
A12: Autismo / TEA | B12: terapia TEA madrid | C12: Transaccional | D12: Alta | E12: /autismo-tea | F12: Centro Juntos | H12: Title
A13: Autismo / TEA | B13: terapia ocupacional autismo | C13: Transaccional | D13: Alta | E13: /autismo-tea | F13: Terapia ocupacional en casa, Eva Téllez | H13: H2
A14: Autismo / TEA | B14: logopeda TEA madrid | C14: Transaccional | D14: Alta | E14: /logopeda-infantil-a-domicilio | F14: Logopedas en Casa, Felisa Casado | H14: H2 logopedia | I14: Logopedas en Casa tiene landing propia con precio 'desde 39 €'.
A15: Autismo / TEA | B15: psicólogo autismo niños madrid | C15: Transaccional | D15: Media | E15: /autismo-tea | F15: Centro Juntos, Clínica T. Aparicio | H15: H2
A16: Autismo / TEA | B16: centros de autismo madrid | C16: Navegacional | D16: Media | E16: /autismo-tea | F16: Directorios (ranking.madrid, espacioautismo) | H16: Texto + ficha en directorios | I16: Aparecer en los directorios que salen en esta búsqueda.
A17: Autismo / TEA | B17: asperger niños terapia madrid | C17: Transaccional | D17: Baja | E17: /autismo-tea | F17: Eva Téllez | H17: Texto | I17: Término antiguo pero aún se busca; mencionar como 'TEA (antes Asperger)'.
A18: TDAH | B18: psicólogo infantil TDAH madrid | C18: Transaccional | D18: Alta | E18: /tdah | F18: Instituto Cláritas, Centro Juntos, IPSIA | H18: Title + H1
A19: TDAH | B19: tratamiento TDAH niños madrid | C19: Transaccional | D19: Alta | E19: /tdah | F19: Doctoralia, Centro Juntos | H19: H2
A20: TDAH | B20: TDAH a domicilio | C20: Transaccional | D20: Media | E20: /tdah | F20: Vértices Psicólogos (apoyo psicoeducativo a domicilio) | H20: H2 | I20: Casi nadie la trabaja: hueco.
A21: TDAH | B21: terapia ocupacional TDAH | C21: Transaccional | D21: Media | E21: /tdah | H21: H2 | I21: Nicho con poca competencia.
A22: TDAH | B22: hiperactividad niños tratamiento | C22: Informativa | D22: Media | E22: /tdah | F22: IPSIA | H22: Texto / FAQ
A23: Neurodesarrollo | B23: trastornos del neurodesarrollo terapia madrid | C23: Transaccional | D23: Media | E23: / (home) o /que-tratamos | F23: Neural KIDS, Imaneuro, Citea | H23: Página '¿En qué os ayudamos?' | I23: Término paraguas para TEA, TDAH, lenguaje, aprendizaje.
A24: Neurodesarrollo | B24: retraso madurativo terapia | C24: Transaccional | D24: Media | E24: /que-tratamos | H24: Texto | I24: Así lo buscan muchas familias aunque vuestra voz dice 'retos en el desarrollo'.
A25: Neurodesarrollo | B25: dificultades de aprendizaje niños madrid | C25: Transaccional | D25: Media | E25: /que-tratamos | F25: Imaneuro, menteAmente | H25: Texto
A26: Neurodesarrollo | B26: problemas de conducta niños psicólogo madrid | C26: Transaccional | D26: Media | E26: /psicologo-infantil-a-domicilio | F26: Centro Juntos | H26: H2
A27: Diagnóstico / neuropsicología | B27: evaluación neuropsicológica infantil madrid | C27: Transaccional | D27: Alta | E27: /evaluacion-neuropsicologica | F27: menteAmente, Ideum, Astrane, Nadia Sánchez | H27: Title + H1 | I27: Ya tenéis la página: reforzarla.
A28: Diagnóstico / neuropsicología | B28: diagnóstico TDAH niños madrid | C28: Transaccional | D28: Alta | E28: /evaluacion-neuropsicologica | F28: Clínica NEA, Doctoralia, menteAmente | H28: H2
A29: Diagnóstico / neuropsicología | B29: diagnóstico autismo niños madrid | C29: Transaccional | D29: Alta | E29: /evaluacion-neuropsicologica | F29: Clínica T. Aparicio, CADE | H29: H2 | I29: Revisar con el equipo qué pruebas y perfiles profesionales firman el informe antes de publicarlo.
A30: Diagnóstico / neuropsicología | B30: evaluación neuropsicológica precio madrid | C30: Transaccional | D30: Alta | E30: /evaluacion-neuropsicologica | F30: menteAmente (página de tarifas) | H30: Bloque de precio | I30: Mostrar precio o 'desde' gana clics.
A31: Diagnóstico / neuropsicología | B31: neuropsicólogo infantil madrid | C31: Transaccional | D31: Media | E31: /evaluacion-neuropsicologica | F31: Ideum, Nadia Sánchez | H31: Texto
A32: Diagnóstico / neuropsicología | B32: evaluación psicopedagógica niños | C32: Transaccional | D32: Baja | E32: /evaluacion-neuropsicologica | F32: CADE | H32: FAQ | I32: Explicar la diferencia con la neuropsicológica.
A33: Sombra / colegio | B33: maestro sombra madrid | C33: Transaccional | D33: Alta | E33: /acompanamiento-sombra-colegio | F33: Mondo Lirondo, Imaneuro | H33: H2 | I33: El término más buscado por familias. Confirmar que ofrecéis el servicio.
A34: Sombra / colegio | B34: terapeuta sombra madrid | C34: Transaccional | D34: Alta | E34: /acompanamiento-sombra-colegio | F34: Imaneuro, Mondo Lirondo | H34: Title + H1
A35: Sombra / colegio | B35: acompañamiento sombra colegio | C35: Transaccional | D35: Alta | E35: /acompanamiento-sombra-colegio | H35: H1 | I35: Término vuestro; poca competencia.
A36: Sombra / colegio | B36: acompañante escolar autismo | C36: Transaccional | D36: Media | E36: /acompanamiento-sombra-colegio | H36: H2
A37: Sombra / colegio | B37: maestro sombra qué es | C37: Informativa | D37: Media | E37: /blog/que-es-un-maestro-sombra | F37: CEAC, MEDAC, abascool | H37: Artículo de blog | I37: Tratar el debate de la inclusión: el objetivo es la autonomía y retirarse poco a poco.
A38: Sombra / colegio | B38: terapia en el colegio madrid | C38: Transaccional | D38: Media | E38: /terapia-en-el-colegio | F38: Imaneuro ('terapia en centro educativo') | H38: H1
A39: Sombra / colegio | B39: coordinación colegio terapeuta | C39: Informativa | D39: Baja | E39: /terapia-en-el-colegio | H39: Texto
A40: Terapia ocupacional | B40: terapia ocupacional infantil madrid | C40: Transaccional | D40: Alta | E40: /terapia-ocupacional-infantil-a-domicilio | F40: Eva Téllez, Centro Juntos, La Salle | H40: Title + H1
A41: Terapia ocupacional | B41: terapia ocupacional a domicilio madrid | C41: Transaccional | D41: Alta | E41: /terapia-ocupacional-infantil-a-domicilio | F41: Eva Téllez, Terapia ocupacional en casa, Doctoralia | H41: H1 | I41: Eva Téllez posiciona con páginas por zona.
...

Sheet Competidores
A1: Competidor | B1: Web | C1: Ubicación | D1: Qué ofrece | E1: Title / H1 de su web (palabras clave que usan) | F1: Lo que hacen bien en SEO | G1: Hueco para PasiTOs | H1: Tipo
A2: Codo con Codo TEA | B2: codoconcodotea.es | C2: Madrid | D2: Terapia a domicilio para niños con autismo, asesoramiento, formación. Aceptan cheque servicio. | E2: Title: «Terapia a Domicilio para Niños con Autismo». H1: «Terapia a domicilio para niños y niñas con autismo, asesoramiento y formaciones». | F2: Keyword exacta en title, H1 y meta. | G2: Solo TEA; no cubren TDAH, logopedia ni evaluación. PasiTOs puede competir con un equipo más amplio. | H2: Directo
A3: Eva Téllez | B3: evatellez.com | C3: Madrid este (22 zonas: Salamanca, Retiro, Vallecas, Coslada, Rivas, Torrejón…) | D3: Terapia ocupacional infantil a domicilio y asesoramiento online. | E3: Title: «Terapia ocupacional infantil en Madrid a domicilio». H1: «Terapia Ocupacional Infantil». | F3: Lista de zonas y de diagnósticos (TEA, TDAH, TEL, síndromes); blog de infancia. | G3: Profesional individual: no hay logopedia, psicología ni neuropsicología. | H3: Directo
A4: Logopedas en Casa | B4: logopedasencasa.com | C4: Madrid (17 distritos) | D4: Logopedia a domicilio infantil y adultos; landings por patología (TEA, atención temprana). | E4: Title: «Logopeda para TEA en Madrid desde 39€ - Especialista en Autismo». H1: «Logopeda para TEA a domicilio en Madrid». | F4: Una landing por patología, precio en el title, FAQ, barrios. | G4: Usan «resultados garantizados» (vosotros no). Sin TO ni psicología infantil. | H4: Directo
A5: Terapia ocupacional en casa (Irene Pascual) | B5: terapiaocupacionalencasa.es | C5: Hortaleza, Madrid | D5: TO a domicilio para niños y adultos; autismo e integración sensorial. | E5: Title: «Terapia ocupacional a domicilio - terapia ocupacional en casa». | F5: Keyword exacta «terapia ocupacional en casa». | G5: Web personal; mezcla infancia y adultos. | H5: Directo
A6: Imaneuro | B6: imaneuro.es | C6: Torrejón de Ardoz | D6: Centro: terapeuta sombra, terapia en centro educativo, neuropsicología, logopedia, TO. | E6: Title: «Imaneuro | Centro de Terapias y Psicología en Torrejón de Ardoz». Servicio «Terapeuta sombra». | F6: Página propia de terapeuta sombra; menciona trastornos del neurodesarrollo. | G6: Local de Torrejón; la página de sombra no carga (error 404). | H6: Directo (sombra)
A7: Centro Mondo Lirondo | B7: centromondolirondo.com | C7: Ensanche de Vallecas | D7: Centro con servicio de terapeuta sombra. | E7: Title: «Terapeuta sombra | Centro Mondo Lirondo». Meta: «El terapeuta sombra o maestro sombra es una figura…». | F7: Usa a la vez «terapeuta sombra» y «maestro sombra». | G7: Página corta y sin FAQ ni precio. | H7: Directo (sombra)
A8: Felisa Casado · Logopedia en contexto natural | B8: logopediacontextonatural.com | C8: Madrid | D8: Logopedia a domicilio para niños con TEA. | E8: Title: «Logopedia a domicilio para niños con TEA». | F8: El dominio contiene «contexto natural». | G8: No se pudo leer la web (bloqueo); revisar a mano. | H8: Directo
A9: Centro Juntos | B9: centrojuntos.es | C9: Chamberí (centro físico) | D9: Atención temprana, logopedia, TO, integración sensorial, psicología, fisio, grupos de habilidades sociales. | E9: Title home: «Tu Centro de Atención Temprana | Atención temprana en Madrid». TEA: «Psicólogo para TEA o autismo». Landings de TDAH, integración sensorial y psicomotricidad. | F9: Una landing por patología y por terapia; aparece en casi todas las búsquedas. | G9: Centro físico; nada a domicilio ni en colegio. | H9: Indirecto (líder SEO)
A10: menteAmente | B10: menteamente.com | C10: Madrid (C. Máiquez) | D10: Neuropsicología infantil y adultos: evaluación TDAH, TEA, aprendizaje. | E10: Title: «Clínica de neuropsicología en Madrid | Niños y adultos». Tiene página «tarifas-neuropsicologo-madrid». | F10: Página de precios propia que posiciona. | G10: En clínica; no hay terapia posterior en casa. | H10: Indirecto (evaluación)
A11: Abaterapia | B11: abaterapia.com | C11: Tres Cantos | D11: Terapia ABA para autismo; empieza en el ambiente natural del niño. | E11: «Terapia ABA Madrid · Especialistas en Autismo». | F11: Contenido largo explicativo sobre ABA. | G11: Metodología única (ABA). | H11: Indirecto
A12: Logopeda Domicilio Madrid | B12: logopedadomicilio.es | C12: Madrid (Castellana) | D12: Logopedia niños y adultos a domicilio. | E12: Title: «Logopeda Domicilio Madrid - Servicios de Logopedia a domicilio Madrid». | F12: Dominio exacto. | G12: No especializado en infancia ni neurodesarrollo. | H12: Indirecto
A13: Directorios | B13: Doctoralia, Top Doctors, MundoPsicologos, Salucity, TEADORO, ranking.madrid | C13: Madrid | D13: Listados de profesionales. | E13: Salen arriba en «TDAH Madrid», «TEA Madrid», «terapeuta ocupacional infantil Madrid». | F13: Autoridad de dominio muy alta. | G13: Daros de alta con ficha completa: es la vía rápida para aparecer en esas búsquedas. | H13: Canal

Sheet Páginas y títulos
A1: Página (URL) | B1: Palabra clave principal | C1: Title propuesto (máx. 60) | D1: Nº caracteres title | E1: Meta description propuesta (máx. 155) | F1: Nº caracteres meta | G1: H1 propuesto
A2: / | B2: terapia infantil a domicilio madrid | C2: Terapia infantil a domicilio en Madrid | Proyecto PasiTOs | D2: =LEN(C2) -> 57 | E2: Terapia ocupacional, logopedia y psicología infantil en casa y en el cole. Centro acreditado por la Comunidad de Madrid. Te asesoramos gratis. | F2: =LEN(E2) -> 142 | G2: Terapia infantil a domicilio y en el cole, en Madrid
A3: /autismo-tea | B3: terapia a domicilio niños con autismo | C3: Terapia para niños con autismo (TEA) a domicilio | PasiTOs | D3: =LEN(C3) -> 58 | E3: Terapia ocupacional, logopedia y psicología para niños con TEA en casa y en el colegio. Nos coordinamos con su cole. Madrid. | F3: =LEN(E3) -> 124 | G3: Terapia a domicilio para niños con autismo (TEA)
A4: /tdah | B4: psicólogo infantil TDAH madrid | C4: TDAH en niños: terapia a domicilio en Madrid | PasiTOs | D4: =LEN(C4) -> 54 | E4: Psicología y terapia ocupacional para niños con TDAH en casa y en el cole. Estrategias para el día a día de la familia. | F4: =LEN(E4) -> 119 | G4: Terapia para niños con TDAH, en casa y en el cole
A5: /evaluacion-neuropsicologica | B5: evaluación neuropsicológica infantil madrid | C5: Evaluación neuropsicológica infantil y diagnóstico | PasiTOs | D5: =LEN(C5) -> 60 | E5: Evaluación neuropsicológica para TDAH, TEA y dificultades de aprendizaje. Entendemos cómo procesa tu hijo y te damos un plan. Madrid. | F5: =LEN(E5) -> 133 | G5: Evaluación neuropsicológica infantil y diagnóstico
A6: /acompanamiento-sombra-colegio | B6: terapeuta sombra madrid | C6: Acompañamiento sombra en el colegio (maestro sombra) | PasiTOs | D6: =LEN(C6) -> 62 | E6: Terapeuta sombra en el aula para niños con TEA o TDAH en Madrid. Objetivo: autonomía y participación con sus compañeros. | F6: =LEN(E6) -> 120 | G6: Acompañamiento sombra en el colegio
A7: /terapia-ocupacional-infantil-a-domicilio | B7: terapia ocupacional a domicilio madrid | C7: Terapia ocupacional infantil a domicilio en Madrid | PasiTOs | D7: =LEN(C7) -> 60 | E7: Terapeutas ocupacionales infantiles en casa y en el colegio: autonomía, integración sensorial, motricidad y alimentación. | F7: =LEN(E7) -> 121 | G7: Terapia ocupacional infantil a domicilio
A8: /integracion-sensorial | B8: integración sensorial madrid | C8: Integración sensorial para niños en casa | Madrid | PasiTOs | D8: =LEN(C8) -> 59 | E8: Terapia de integración sensorial en el entorno del niño, con estrategias para casa y cole. Terapeutas ocupacionales infantiles. | F8: =LEN(E8) -> 127 | G8: Integración sensorial en casa y en el cole
A9: /logopeda-infantil-a-domicilio | B9: logopeda infantil a domicilio madrid | C9: Logopeda infantil a domicilio en Madrid | Proyecto PasiTOs | D9: =LEN(C9) -> 58 | E9: Logopedia para niños en casa: retraso del lenguaje, TEA y comunicación. Coordinación con el colegio. | F9: =LEN(E9) -> 100 | G9: Logopeda infantil a domicilio en Madrid
A10: /psicologo-infantil-a-domicilio | B10: psicólogo infantil a domicilio madrid | C10: Psicólogo infantil a domicilio en Madrid | Proyecto PasiTOs | D10: =LEN(C10) -> 59 | E10: Psicología infantil en casa: conducta, emociones, TDAH y TEA. Apoyo y estrategias para toda la familia. | F10: =LEN(E10) -> 103 | G10: Psicólogo infantil a domicilio
A11: /cheque-servicio | B11: cheque servicio comunidad de madrid | C11: Cheque servicio Comunidad de Madrid: cómo pedirlo | PasiTOs | D11: =LEN(C11) -> 59 | E11: Qué es el cheque servicio, quién puede pedirlo y cómo usarlo en terapia infantil. Somos centro acreditado (S8268). | F11: =LEN(E11) -> 114 | G11: Cheque servicio de la Comunidad de Madrid
A13: Las celdas se ponen en rojo si el title pasa de 60 caracteres o la meta de 155 (Google los corta).

Sheet Preguntas blog-FAQ
A1: Pregunta que hacen las familias | B1: Cluster | C1: Formato | D1: Página donde enlazar
A2: ¿Cómo saber si mi hijo tiene autismo? Señales por edad | B2: Autismo / TEA | C2: Blog | D2: /autismo-tea
A3: ¿Qué terapias necesita un niño con autismo? | B3: Autismo / TEA | C3: Blog | D3: /autismo-tea
A4: ¿Terapia en casa o en un centro? Qué dice la evidencia | B4: A domicilio (núcleo) | C4: Blog | D4: /
A5: ¿Qué es la terapia ocupacional infantil y cuándo se necesita? | B5: Terapia ocupacional | C5: Blog + FAQ | D5: /terapia-ocupacional-infantil-a-domicilio
A6: ¿Qué es la integración sensorial? | B6: Terapia ocupacional | C6: Blog | D6: /integracion-sensorial
A7: Mi hijo solo quiere comer patatas fritas: ¿es selectividad alimentaria? | B7: Terapia ocupacional | C7: Blog | D7: /terapia-ocupacional-infantil-a-domicilio
A8: Mi hijo no habla a los 2 años: ¿cuándo ir al logopeda? | B8: Logopedia | C8: Blog | D8: /logopeda-infantil-a-domicilio
A9: Síntomas de TDAH en niños: qué observar en casa y en el cole | B9: TDAH | C9: Blog | D9: /tdah
A10: ¿Cómo se diagnostica el TDAH en niños? | B10: Diagnóstico / neuropsicología | C10: Blog + FAQ | D10: /evaluacion-neuropsicologica
A11: ¿Qué es una evaluación neuropsicológica y cuánto cuesta? | B11: Diagnóstico / neuropsicología | C11: FAQ | D11: /evaluacion-neuropsicologica
A12: ¿Qué es un maestro sombra y cuándo lo necesita un niño? | B12: Sombra / colegio | C12: Blog | D12: /acompanamiento-sombra-colegio
... A18: ¿Hace falta preparar algo en casa para la primera valoración? | B18: A domicilio (núcleo) | C18: FAQ | D18: /

Sheet Fuentes y método
A1: Método
A2: 1. Búsquedas en Google (29-09-2026) de las combinaciones que usan las familias: terapia, autismo/TEA, TDAH, neurodesarrollo, diagnóstico, maestro/terapeuta sombra, logopeda, terapia ocupacional, integración sensorial, cheque servicio, siempre con 'Madrid' y 'a domicilio'.
A3: 2. Lectura del title, meta description y encabezados de las webs competidoras que salen en esos resultados.
A4: 3. Priorización según encaje con vuestros servicios, intención de contratar y competencia observada.
A5: Límite: no hay datos de volumen de búsqueda. Rellenadlos con Google Keyword Planner (gratis con una cuenta de Google Ads) o con Google Search Console de la web actual.
A7: Fuentes consultadas
A8: https://codoconcodotea.es/
A9: https://evatellez.com/terapia-ocupacional-infantil/
A10: https://logopedasencasa.com/logopeda-tea
A11: https://terapiaocupacionalencasa.es/sobre-mi
A12: https://imaneuro.es/
A13: https://www.centromondolirondo.com/terapeuta-sombra
... A21: https://abcnoticias.mx/local/2026/9/10/concepto-de-maestro-sombra-en-escuelas-es-excluyente-para-ninos-con-autismo-expertos-289363.html (debate sobre la figura del maestro sombra)
